2018-08-28 09:11:44,592 ERROR: Exception on /main/upload [POST] [in /Users/darren/anaconda3/envs/heroku-webapp/lib/python3.6/site-packages/flask/app.py:1761]
Traceback (most recent call last):
  File "/Users/darren/anaconda3/envs/heroku-webapp/lib/python3.6/site-packages/flask/app.py", line 2292, in wsgi_app
    response = self.full_dispatch_request()
  File "/Users/darren/anaconda3/envs/heroku-webapp/lib/python3.6/site-packages/flask/app.py", line 1815, in full_dispatch_request
    rv = self.handle_user_exception(e)
  File "/Users/darren/anaconda3/envs/heroku-webapp/lib/python3.6/site-packages/flask/app.py", line 1718, in handle_user_exception
    reraise(exc_type, exc_value, tb)
  File "/Users/darren/anaconda3/envs/heroku-webapp/lib/python3.6/site-packages/flask/_compat.py", line 35, in reraise
    raise value
  File "/Users/darren/anaconda3/envs/heroku-webapp/lib/python3.6/site-packages/flask/app.py", line 1813, in full_dispatch_request
    rv = self.dispatch_request()
  File "/Users/darren/anaconda3/envs/heroku-webapp/lib/python3.6/site-packages/flask/app.py", line 1799, in dispatch_request
    return self.view_functions[rule.endpoint](**req.view_args)
  File "/Users/darren/anaconda3/envs/heroku-webapp/lib/python3.6/site-packages/flask_login/utils.py", line 261, in decorated_view
    return func(*args, **kwargs)
  File "/Users/darren/PycharmProjects/modern-money-box/app/main/routes.py", line 93, in upload_file
    debit = row[4]
IndexError: list index out of range
2018-08-28 09:12:10,125 INFO: Moneybox startup [in /Users/darren/PycharmProjects/modern-money-box/app/__init__.py:55]
2018-08-28 09:13:07,023 INFO: Moneybox startup [in /Users/darren/PycharmProjects/modern-money-box/app/__init__.py:55]
2018-08-28 09:14:24,227 INFO: Moneybox startup [in /Users/darren/PycharmProjects/modern-money-box/app/__init__.py:55]
2018-08-28 09:15:51,588 INFO: Moneybox startup [in /Users/darren/PycharmProjects/modern-money-box/app/__init__.py:55]
2018-08-28 09:18:35,303 INFO: Moneybox startup [in /Users/darren/PycharmProjects/modern-money-box/app/__init__.py:55]
2018-08-28 09:18:39,255 ERROR: Exception on /main/upload [POST] [in /Users/darren/anaconda3/envs/heroku-webapp/lib/python3.6/site-packages/flask/app.py:1761]
Traceback (most recent call last):
  File "/Users/darren/anaconda3/envs/heroku-webapp/lib/python3.6/site-packages/sqlalchemy/engine/base.py", line 1193, in _execute_context
    context)
  File "/Users/darren/anaconda3/envs/heroku-webapp/lib/python3.6/site-packages/sqlalchemy/engine/default.py", line 508, in do_execute
    cursor.execute(statement, parameters)
psycopg2.ProgrammingError: can't adapt type 'TransactionType'

The above exception was the direct cause of the following exception:

Traceback (most recent call last):
  File "/Users/darren/anaconda3/envs/heroku-webapp/lib/python3.6/site-packages/flask/app.py", line 2292, in wsgi_app
    response = self.full_dispatch_request()
  File "/Users/darren/anaconda3/envs/heroku-webapp/lib/python3.6/site-packages/flask/app.py", line 1815, in full_dispatch_request
    rv = self.handle_user_exception(e)
  File "/Users/darren/anaconda3/envs/heroku-webapp/lib/python3.6/site-packages/flask/app.py", line 1718, in handle_user_exception
    reraise(exc_type, exc_value, tb)
  File "/Users/darren/anaconda3/envs/heroku-webapp/lib/python3.6/site-packages/flask/_compat.py", line 35, in reraise
    raise value
  File "/Users/darren/anaconda3/envs/heroku-webapp/lib/python3.6/site-packages/flask/app.py", line 1813, in full_dispatch_request
    rv = self.dispatch_request()
  File "/Users/darren/anaconda3/envs/heroku-webapp/lib/python3.6/site-packages/flask/app.py", line 1799, in dispatch_request
    return self.view_functions[rule.endpoint](**req.view_args)
  File "/Users/darren/anaconda3/envs/heroku-webapp/lib/python3.6/site-packages/flask_login/utils.py", line 261, in decorated_view
    return func(*args, **kwargs)
  File "/Users/darren/PycharmProjects/modern-money-box/app/main/routes.py", line 110, in upload_file
    db.session.commit()
  File "/Users/darren/anaconda3/envs/heroku-webapp/lib/python3.6/site-packages/sqlalchemy/orm/scoping.py", line 153, in do
    return getattr(self.registry(), name)(*args, **kwargs)
  File "/Users/darren/anaconda3/envs/heroku-webapp/lib/python3.6/site-packages/sqlalchemy/orm/session.py", line 943, in commit
    self.transaction.commit()
  File "/Users/darren/anaconda3/envs/heroku-webapp/lib/python3.6/site-packages/sqlalchemy/orm/session.py", line 467, in commit
    self._prepare_impl()
  File "/Users/darren/anaconda3/envs/heroku-webapp/lib/python3.6/site-packages/sqlalchemy/orm/session.py", line 447, in _prepare_impl
    self.session.flush()
  File "/Users/darren/anaconda3/envs/heroku-webapp/lib/python3.6/site-packages/sqlalchemy/orm/session.py", line 2254, in flush
    self._flush(objects)
  File "/Users/darren/anaconda3/envs/heroku-webapp/lib/python3.6/site-packages/sqlalchemy/orm/session.py", line 2380, in _flush
    transaction.rollback(_capture_exception=True)
  File "/Users/darren/anaconda3/envs/heroku-webapp/lib/python3.6/site-packages/sqlalchemy/util/langhelpers.py", line 66, in __exit__
    compat.reraise(exc_type, exc_value, exc_tb)
  File "/Users/darren/anaconda3/envs/heroku-webapp/lib/python3.6/site-packages/sqlalchemy/util/compat.py", line 187, in reraise
    raise value
  File "/Users/darren/anaconda3/envs/heroku-webapp/lib/python3.6/site-packages/sqlalchemy/orm/session.py", line 2344, in _flush
    flush_context.execute()
  File "/Users/darren/anaconda3/envs/heroku-webapp/lib/python3.6/site-packages/sqlalchemy/orm/unitofwork.py", line 391, in execute
    rec.execute(self)
  File "/Users/darren/anaconda3/envs/heroku-webapp/lib/python3.6/site-packages/sqlalchemy/orm/unitofwork.py", line 556, in execute
    uow
  File "/Users/darren/anaconda3/envs/heroku-webapp/lib/python3.6/site-packages/sqlalchemy/orm/persistence.py", line 181, in save_obj
    mapper, table, insert)
  File "/Users/darren/anaconda3/envs/heroku-webapp/lib/python3.6/site-packages/sqlalchemy/orm/persistence.py", line 866, in _emit_insert_statements
    execute(statement, params)
  File "/Users/darren/anaconda3/envs/heroku-webapp/lib/python3.6/site-packages/sqlalchemy/engine/base.py", line 948, in execute
    return meth(self, multiparams, params)
  File "/Users/darren/anaconda3/envs/heroku-webapp/lib/python3.6/site-packages/sqlalchemy/sql/elements.py", line 269, in _execute_on_connection
    return connection._execute_clauseelement(self, multiparams, params)
  File "/Users/darren/anaconda3/envs/heroku-webapp/lib/python3.6/site-packages/sqlalchemy/engine/base.py", line 1060, in _execute_clauseelement
    compiled_sql, distilled_params
  File "/Users/darren/anaconda3/envs/heroku-webapp/lib/python3.6/site-packages/sqlalchemy/engine/base.py", line 1200, in _execute_context
    context)
  File "/Users/darren/anaconda3/envs/heroku-webapp/lib/python3.6/site-packages/sqlalchemy/engine/base.py", line 1413, in _handle_dbapi_exception
    exc_info
  File "/Users/darren/anaconda3/envs/heroku-webapp/lib/python3.6/site-packages/sqlalchemy/util/compat.py", line 203, in raise_from_cause
    reraise(type(exception), exception, tb=exc_tb, cause=cause)
  File "/Users/darren/anaconda3/envs/heroku-webapp/lib/python3.6/site-packages/sqlalchemy/util/compat.py", line 186, in reraise
    raise value.with_traceback(tb)
  File "/Users/darren/anaconda3/envs/heroku-webapp/lib/python3.6/site-packages/sqlalchemy/engine/base.py", line 1193, in _execute_context
    context)
  File "/Users/darren/anaconda3/envs/heroku-webapp/lib/python3.6/site-packages/sqlalchemy/engine/default.py", line 508, in do_execute
    cursor.execute(statement, parameters)
sqlalchemy.exc.ProgrammingError: (psycopg2.ProgrammingError) can't adapt type 'TransactionType' [SQL: 'INSERT INTO transaction (amount, type, description, created_date, account_id) VALUES (%(amount)s, %(type)s, %(description)s, %(created_date)s, %(account_id)s) RETURNING transaction.id'] [parameters: {'amount': '0.5', 'type': <TransactionType.DEBIT: 'D'>, 'description': 'Late in morning', 'created_date': '08/23/18', 'account_id': 3}] (Background on this error at: http://sqlalche.me/e/f405)
2018-08-28 09:19:13,959 INFO: Moneybox startup [in /Users/darren/PycharmProjects/modern-money-box/app/__init__.py:55]
2018-08-28 09:55:23,753 INFO: Moneybox startup [in /Users/darren/PycharmProjects/modern-money-box/app/__init__.py:55]
2018-08-28 09:55:47,033 ERROR: Exception on /main/upload [POST] [in /Users/darren/anaconda3/envs/heroku-webapp/lib/python3.6/site-packages/flask/app.py:1761]
Traceback (most recent call last):
  File "/Users/darren/anaconda3/envs/heroku-webapp/lib/python3.6/site-packages/flask/app.py", line 2292, in wsgi_app
    response = self.full_dispatch_request()
  File "/Users/darren/anaconda3/envs/heroku-webapp/lib/python3.6/site-packages/flask/app.py", line 1815, in full_dispatch_request
    rv = self.handle_user_exception(e)
  File "/Users/darren/anaconda3/envs/heroku-webapp/lib/python3.6/site-packages/flask/app.py", line 1718, in handle_user_exception
    reraise(exc_type, exc_value, tb)
  File "/Users/darren/anaconda3/envs/heroku-webapp/lib/python3.6/site-packages/flask/_compat.py", line 35, in reraise
    raise value
  File "/Users/darren/anaconda3/envs/heroku-webapp/lib/python3.6/site-packages/flask/app.py", line 1813, in full_dispatch_request
    rv = self.dispatch_request()
  File "/Users/darren/anaconda3/envs/heroku-webapp/lib/python3.6/site-packages/flask/app.py", line 1799, in dispatch_request
    return self.view_functions[rule.endpoint](**req.view_args)
  File "/Users/darren/anaconda3/envs/heroku-webapp/lib/python3.6/site-packages/flask_login/utils.py", line 261, in decorated_view
    return func(*args, **kwargs)
  File "/Users/darren/PycharmProjects/modern-money-box/app/main/routes.py", line 110, in upload_file
    current_account.balance = current_account.balance - debit
TypeError: unsupported operand type(s) for -: 'decimal.Decimal' and 'str'
2018-08-28 09:57:46,695 INFO: Moneybox startup [in /Users/darren/PycharmProjects/modern-money-box/app/__init__.py:55]
